fassihbe@FGDBe:~/Git/holbertonschool-hbnb/part2$ coverage run --rcfile=../.coveragerc -m unittest discover app/
...E...F.E.E..EEEEEEEEEE...E...FEEEEEEEE...E...F
======================================================================
ERROR: test_get_by_id (tests.test_models.test_amenity.TestAmenity)
----------------------------------------------------------------------
Traceback (most recent call last):
  File "/home/fassihbe/Git/holbertonschool-hbnb/part2/app/tests/test_models/test_amenity.py", line 34, in test_get_by_id
    self.assertEqual(amenity.id, self.amenity.id)
AttributeError: 'NoneType' object has no attribute 'id'

======================================================================
ERROR: test_create (tests.test_models.test_basemodel.TestBaseModel)
----------------------------------------------------------------------
Traceback (most recent call last):
  File "/home/fassihbe/Git/holbertonschool-hbnb/part2/app/tests/test_models/test_basemodel.py", line 28, in test_create
    new_basemodel = BaseModel.create(**self.valid_params)
AttributeError: type object 'BaseModel' has no attribute 'create'

======================================================================
ERROR: test_get_by_id (tests.test_models.test_basemodel.TestBaseModel)
----------------------------------------------------------------------
Traceback (most recent call last):
  File "/home/fassihbe/Git/holbertonschool-hbnb/part2/app/tests/test_models/test_basemodel.py", line 33, in test_get_by_id
    basemodel = BaseModel.get_by_id(self.basemodel.id)
AttributeError: type object 'BaseModel' has no attribute 'get_by_id'

======================================================================
ERROR: test_update (tests.test_models.test_basemodel.TestBaseModel)
----------------------------------------------------------------------
Traceback (most recent call last):
  File "/home/fassihbe/Git/holbertonschool-hbnb/part2/app/tests/test_models/test_basemodel.py", line 42, in test_update
    self.basemodel.update(update_data)
AttributeError: 'BaseModel' object has no attribute 'update'

======================================================================
ERROR: test_update_with_invalid_params (tests.test_models.test_basemodel.TestBaseModel)
----------------------------------------------------------------------
Traceback (most recent call last):
  File "/home/fassihbe/Git/holbertonschool-hbnb/part2/app/tests/test_models/test_basemodel.py", line 61, in test_update_with_invalid_params
    self.basemodel.update({'invalid_param': 'invalid_value'})
AttributeError: 'BaseModel' object has no attribute 'update'

======================================================================
ERROR: test_attributes (tests.test_models.test_place.TestPlace)
----------------------------------------------------------------------
Traceback (most recent call last):
  File "/home/fassihbe/Git/holbertonschool-hbnb/part2/app/tests/test_models/test_place.py", line 11, in setUp
    self.valid_params = {'name': 'task', 'description': 'Issue work good body billion such. Popular opportunity evidence continue.\nItself leader do show important be write. Player billion ahead site decide require.\nDecision experience save organization next dinner while. Relationship force cultural management return. When small challenge wife.\nSister front a rest democratic serious college. Place reality own election move provide.\nExpert administration special prepare every song hear.', 'number_rooms': 8, 'number_bathrooms': 10, 'max_guest': 'laugh', 'price_by_night': 336.46, 'latitude': Decimal('59.4132055'), 'longitude': Decimal('-80.982168'), 'owner_id': 'a5aee83a-76b4-4350-a6db-42c6bdf2a8a2', 'city': 'our', 'country': 'benefit'}
NameError: name 'Decimal' is not defined

======================================================================
ERROR: test_create (tests.test_models.test_place.TestPlace)
----------------------------------------------------------------------
Traceback (most recent call last):
  File "/home/fassihbe/Git/holbertonschool-hbnb/part2/app/tests/test_models/test_place.py", line 11, in setUp
    self.valid_params = {'name': 'task', 'description': 'Issue work good body billion such. Popular opportunity evidence continue.\nItself leader do show important be write. Player billion ahead site decide require.\nDecision experience save organization next dinner while. Relationship force cultural management return. When small challenge wife.\nSister front a rest democratic serious college. Place reality own election move provide.\nExpert administration special prepare every song hear.', 'number_rooms': 8, 'number_bathrooms': 10, 'max_guest': 'laugh', 'price_by_night': 336.46, 'latitude': Decimal('59.4132055'), 'longitude': Decimal('-80.982168'), 'owner_id': 'a5aee83a-76b4-4350-a6db-42c6bdf2a8a2', 'city': 'our', 'country': 'benefit'}
NameError: name 'Decimal' is not defined

======================================================================
ERROR: test_create_with_invalid_params (tests.test_models.test_place.TestPlace)
----------------------------------------------------------------------
Traceback (most recent call last):
  File "/home/fassihbe/Git/holbertonschool-hbnb/part2/app/tests/test_models/test_place.py", line 11, in setUp
    self.valid_params = {'name': 'task', 'description': 'Issue work good body billion such. Popular opportunity evidence continue.\nItself leader do show important be write. Player billion ahead site decide require.\nDecision experience save organization next dinner while. Relationship force cultural management return. When small challenge wife.\nSister front a rest democratic serious college. Place reality own election move provide.\nExpert administration special prepare every song hear.', 'number_rooms': 8, 'number_bathrooms': 10, 'max_guest': 'laugh', 'price_by_night': 336.46, 'latitude': Decimal('59.4132055'), 'longitude': Decimal('-80.982168'), 'owner_id': 'a5aee83a-76b4-4350-a6db-42c6bdf2a8a2', 'city': 'our', 'country': 'benefit'}
NameError: name 'Decimal' is not defined

======================================================================
ERROR: test_get_by_id (tests.test_models.test_place.TestPlace)
----------------------------------------------------------------------
Traceback (most recent call last):
  File "/home/fassihbe/Git/holbertonschool-hbnb/part2/app/tests/test_models/test_place.py", line 11, in setUp
    self.valid_params = {'name': 'task', 'description': 'Issue work good body billion such. Popular opportunity evidence continue.\nItself leader do show important be write. Player billion ahead site decide require.\nDecision experience save organization next dinner while. Relationship force cultural management return. When small challenge wife.\nSister front a rest democratic serious college. Place reality own election move provide.\nExpert administration special prepare every song hear.', 'number_rooms': 8, 'number_bathrooms': 10, 'max_guest': 'laugh', 'price_by_night': 336.46, 'latitude': Decimal('59.4132055'), 'longitude': Decimal('-80.982168'), 'owner_id': 'a5aee83a-76b4-4350-a6db-42c6bdf2a8a2', 'city': 'our', 'country': 'benefit'}
NameError: name 'Decimal' is not defined

======================================================================
ERROR: test_methods (tests.test_models.test_place.TestPlace)
----------------------------------------------------------------------
Traceback (most recent call last):
  File "/home/fassihbe/Git/holbertonschool-hbnb/part2/app/tests/test_models/test_place.py", line 11, in setUp
    self.valid_params = {'name': 'task', 'description': 'Issue work good body billion such. Popular opportunity evidence continue.\nItself leader do show important be write. Player billion ahead site decide require.\nDecision experience save organization next dinner while. Relationship force cultural management return. When small challenge wife.\nSister front a rest democratic serious college. Place reality own election move provide.\nExpert administration special prepare every song hear.', 'number_rooms': 8, 'number_bathrooms': 10, 'max_guest': 'laugh', 'price_by_night': 336.46, 'latitude': Decimal('59.4132055'), 'longitude': Decimal('-80.982168'), 'owner_id': 'a5aee83a-76b4-4350-a6db-42c6bdf2a8a2', 'city': 'our', 'country': 'benefit'}
NameError: name 'Decimal' is not defined

======================================================================
ERROR: test_to_dict (tests.test_models.test_place.TestPlace)
----------------------------------------------------------------------
Traceback (most recent call last):
  File "/home/fassihbe/Git/holbertonschool-hbnb/part2/app/tests/test_models/test_place.py", line 11, in setUp
    self.valid_params = {'name': 'task', 'description': 'Issue work good body billion such. Popular opportunity evidence continue.\nItself leader do show important be write. Player billion ahead site decide require.\nDecision experience save organization next dinner while. Relationship force cultural management return. When small challenge wife.\nSister front a rest democratic serious college. Place reality own election move provide.\nExpert administration special prepare every song hear.', 'number_rooms': 8, 'number_bathrooms': 10, 'max_guest': 'laugh', 'price_by_night': 336.46, 'latitude': Decimal('59.4132055'), 'longitude': Decimal('-80.982168'), 'owner_id': 'a5aee83a-76b4-4350-a6db-42c6bdf2a8a2', 'city': 'our', 'country': 'benefit'}
NameError: name 'Decimal' is not defined

======================================================================
ERROR: test_update (tests.test_models.test_place.TestPlace)
----------------------------------------------------------------------
Traceback (most recent call last):
  File "/home/fassihbe/Git/holbertonschool-hbnb/part2/app/tests/test_models/test_place.py", line 11, in setUp
    self.valid_params = {'name': 'task', 'description': 'Issue work good body billion such. Popular opportunity evidence continue.\nItself leader do show important be write. Player billion ahead site decide require.\nDecision experience save organization next dinner while. Relationship force cultural management return. When small challenge wife.\nSister front a rest democratic serious college. Place reality own election move provide.\nExpert administration special prepare every song hear.', 'number_rooms': 8, 'number_bathrooms': 10, 'max_guest': 'laugh', 'price_by_night': 336.46, 'latitude': Decimal('59.4132055'), 'longitude': Decimal('-80.982168'), 'owner_id': 'a5aee83a-76b4-4350-a6db-42c6bdf2a8a2', 'city': 'our', 'country': 'benefit'}
NameError: name 'Decimal' is not defined

======================================================================
ERROR: test_update_with_invalid_params (tests.test_models.test_place.TestPlace)
----------------------------------------------------------------------
Traceback (most recent call last):
  File "/home/fassihbe/Git/holbertonschool-hbnb/part2/app/tests/test_models/test_place.py", line 11, in setUp
    self.valid_params = {'name': 'task', 'description': 'Issue work good body billion such. Popular opportunity evidence continue.\nItself leader do show important be write. Player billion ahead site decide require.\nDecision experience save organization next dinner while. Relationship force cultural management return. When small challenge wife.\nSister front a rest democratic serious college. Place reality own election move provide.\nExpert administration special prepare every song hear.', 'number_rooms': 8, 'number_bathrooms': 10, 'max_guest': 'laugh', 'price_by_night': 336.46, 'latitude': Decimal('59.4132055'), 'longitude': Decimal('-80.982168'), 'owner_id': 'a5aee83a-76b4-4350-a6db-42c6bdf2a8a2', 'city': 'our', 'country': 'benefit'}
NameError: name 'Decimal' is not defined

======================================================================
ERROR: test_get_by_id (tests.test_models.test_placeamenity.TestPlaceAmenity)
----------------------------------------------------------------------
Traceback (most recent call last):
  File "/home/fassihbe/Git/holbertonschool-hbnb/part2/app/tests/test_models/test_placeamenity.py", line 34, in test_get_by_id
    self.assertEqual(placeamenity.id, self.placeamenity.id)
AttributeError: 'NoneType' object has no attribute 'id'

======================================================================
ERROR: test_attributes (tests.test_models.test_review.TestReview)
----------------------------------------------------------------------
Traceback (most recent call last):
  File "/home/fassihbe/Git/holbertonschool-hbnb/part2/app/models/review.py", line 29, in _validate_rating
    rating = int(rating)
ValueError: invalid literal for int() with base 10: 'executive'

During handling of the above exception, another exception occurred:

Traceback (most recent call last):
  File "/home/fassihbe/Git/holbertonschool-hbnb/part2/app/tests/test_models/test_review.py", line 12, in setUp
    self.review = Review(**self.valid_params)
  File "/home/fassihbe/Git/holbertonschool-hbnb/part2/app/models/review.py", line 12, in __init__
    self.rating = self._validate_rating(rating)
  File "/home/fassihbe/Git/holbertonschool-hbnb/part2/app/models/review.py", line 33, in _validate_rating
    raise ValueError("Rating must be an integer between 1 and 5")
ValueError: Rating must be an integer between 1 and 5

======================================================================
ERROR: test_create (tests.test_models.test_review.TestReview)
----------------------------------------------------------------------
Traceback (most recent call last):
  File "/home/fassihbe/Git/holbertonschool-hbnb/part2/app/models/review.py", line 29, in _validate_rating
    rating = int(rating)
ValueError: invalid literal for int() with base 10: 'executive'

During handling of the above exception, another exception occurred:

Traceback (most recent call last):
  File "/home/fassihbe/Git/holbertonschool-hbnb/part2/app/tests/test_models/test_review.py", line 12, in setUp
    self.review = Review(**self.valid_params)
  File "/home/fassihbe/Git/holbertonschool-hbnb/part2/app/models/review.py", line 12, in __init__
    self.rating = self._validate_rating(rating)
  File "/home/fassihbe/Git/holbertonschool-hbnb/part2/app/models/review.py", line 33, in _validate_rating
    raise ValueError("Rating must be an integer between 1 and 5")
ValueError: Rating must be an integer between 1 and 5

======================================================================
ERROR: test_create_with_invalid_params (tests.test_models.test_review.TestReview)
----------------------------------------------------------------------
Traceback (most recent call last):
  File "/home/fassihbe/Git/holbertonschool-hbnb/part2/app/models/review.py", line 29, in _validate_rating
    rating = int(rating)
ValueError: invalid literal for int() with base 10: 'executive'

During handling of the above exception, another exception occurred:

Traceback (most recent call last):
  File "/home/fassihbe/Git/holbertonschool-hbnb/part2/app/tests/test_models/test_review.py", line 12, in setUp
    self.review = Review(**self.valid_params)
  File "/home/fassihbe/Git/holbertonschool-hbnb/part2/app/models/review.py", line 12, in __init__
    self.rating = self._validate_rating(rating)
  File "/home/fassihbe/Git/holbertonschool-hbnb/part2/app/models/review.py", line 33, in _validate_rating
    raise ValueError("Rating must be an integer between 1 and 5")
ValueError: Rating must be an integer between 1 and 5

======================================================================
ERROR: test_get_by_id (tests.test_models.test_review.TestReview)
----------------------------------------------------------------------
Traceback (most recent call last):
  File "/home/fassihbe/Git/holbertonschool-hbnb/part2/app/models/review.py", line 29, in _validate_rating
    rating = int(rating)
ValueError: invalid literal for int() with base 10: 'executive'

During handling of the above exception, another exception occurred:

Traceback (most recent call last):
  File "/home/fassihbe/Git/holbertonschool-hbnb/part2/app/tests/test_models/test_review.py", line 12, in setUp
    self.review = Review(**self.valid_params)
  File "/home/fassihbe/Git/holbertonschool-hbnb/part2/app/models/review.py", line 12, in __init__
    self.rating = self._validate_rating(rating)
  File "/home/fassihbe/Git/holbertonschool-hbnb/part2/app/models/review.py", line 33, in _validate_rating
    raise ValueError("Rating must be an integer between 1 and 5")
ValueError: Rating must be an integer between 1 and 5

======================================================================
ERROR: test_methods (tests.test_models.test_review.TestReview)
----------------------------------------------------------------------
Traceback (most recent call last):
  File "/home/fassihbe/Git/holbertonschool-hbnb/part2/app/models/review.py", line 29, in _validate_rating
    rating = int(rating)
ValueError: invalid literal for int() with base 10: 'executive'

During handling of the above exception, another exception occurred:

Traceback (most recent call last):
  File "/home/fassihbe/Git/holbertonschool-hbnb/part2/app/tests/test_models/test_review.py", line 12, in setUp
    self.review = Review(**self.valid_params)
  File "/home/fassihbe/Git/holbertonschool-hbnb/part2/app/models/review.py", line 12, in __init__
    self.rating = self._validate_rating(rating)
  File "/home/fassihbe/Git/holbertonschool-hbnb/part2/app/models/review.py", line 33, in _validate_rating
    raise ValueError("Rating must be an integer between 1 and 5")
ValueError: Rating must be an integer between 1 and 5

======================================================================
ERROR: test_to_dict (tests.test_models.test_review.TestReview)
----------------------------------------------------------------------
Traceback (most recent call last):
  File "/home/fassihbe/Git/holbertonschool-hbnb/part2/app/models/review.py", line 29, in _validate_rating
    rating = int(rating)
ValueError: invalid literal for int() with base 10: 'executive'

During handling of the above exception, another exception occurred:

Traceback (most recent call last):
  File "/home/fassihbe/Git/holbertonschool-hbnb/part2/app/tests/test_models/test_review.py", line 12, in setUp
    self.review = Review(**self.valid_params)
  File "/home/fassihbe/Git/holbertonschool-hbnb/part2/app/models/review.py", line 12, in __init__
    self.rating = self._validate_rating(rating)
  File "/home/fassihbe/Git/holbertonschool-hbnb/part2/app/models/review.py", line 33, in _validate_rating
    raise ValueError("Rating must be an integer between 1 and 5")
ValueError: Rating must be an integer between 1 and 5

======================================================================
ERROR: test_update (tests.test_models.test_review.TestReview)
----------------------------------------------------------------------
Traceback (most recent call last):
  File "/home/fassihbe/Git/holbertonschool-hbnb/part2/app/models/review.py", line 29, in _validate_rating
    rating = int(rating)
ValueError: invalid literal for int() with base 10: 'executive'

During handling of the above exception, another exception occurred:

Traceback (most recent call last):
  File "/home/fassihbe/Git/holbertonschool-hbnb/part2/app/tests/test_models/test_review.py", line 12, in setUp
    self.review = Review(**self.valid_params)
  File "/home/fassihbe/Git/holbertonschool-hbnb/part2/app/models/review.py", line 12, in __init__
    self.rating = self._validate_rating(rating)
  File "/home/fassihbe/Git/holbertonschool-hbnb/part2/app/models/review.py", line 33, in _validate_rating
    raise ValueError("Rating must be an integer between 1 and 5")
ValueError: Rating must be an integer between 1 and 5

======================================================================
ERROR: test_update_with_invalid_params (tests.test_models.test_review.TestReview)
----------------------------------------------------------------------
Traceback (most recent call last):
  File "/home/fassihbe/Git/holbertonschool-hbnb/part2/app/models/review.py", line 29, in _validate_rating
    rating = int(rating)
ValueError: invalid literal for int() with base 10: 'executive'

During handling of the above exception, another exception occurred:

Traceback (most recent call last):
  File "/home/fassihbe/Git/holbertonschool-hbnb/part2/app/tests/test_models/test_review.py", line 12, in setUp
    self.review = Review(**self.valid_params)
  File "/home/fassihbe/Git/holbertonschool-hbnb/part2/app/models/review.py", line 12, in __init__
    self.rating = self._validate_rating(rating)
  File "/home/fassihbe/Git/holbertonschool-hbnb/part2/app/models/review.py", line 33, in _validate_rating
    raise ValueError("Rating must be an integer between 1 and 5")
ValueError: Rating must be an integer between 1 and 5

======================================================================
ERROR: test_get_by_id (tests.test_models.test_user.TestUser)
----------------------------------------------------------------------
Traceback (most recent call last):
  File "/home/fassihbe/Git/holbertonschool-hbnb/part2/app/tests/test_models/test_user.py", line 34, in test_get_by_id
    self.assertEqual(user.id, self.user.id)
AttributeError: 'NoneType' object has no attribute 'id'

======================================================================
FAIL: test_update_with_invalid_params (tests.test_models.test_amenity.TestAmenity)
----------------------------------------------------------------------
Traceback (most recent call last):
  File "/home/fassihbe/Git/holbertonschool-hbnb/part2/app/tests/test_models/test_amenity.py", line 60, in test_update_with_invalid_params
    with self.assertRaises(ValueError):
AssertionError: ValueError not raised

======================================================================
FAIL: test_update_with_invalid_params (tests.test_models.test_placeamenity.TestPlaceAmenity)
----------------------------------------------------------------------
Traceback (most recent call last):
  File "/home/fassihbe/Git/holbertonschool-hbnb/part2/app/tests/test_models/test_placeamenity.py", line 60, in test_update_with_invalid_params
    with self.assertRaises(ValueError):
AssertionError: ValueError not raised

======================================================================
FAIL: test_update_with_invalid_params (tests.test_models.test_user.TestUser)
----------------------------------------------------------------------
Traceback (most recent call last):
  File "/home/fassihbe/Git/holbertonschool-hbnb/part2/app/tests/test_models/test_user.py", line 60, in test_update_with_invalid_params
    with self.assertRaises(ValueError):
AssertionError: ValueError not raised

----------------------------------------------------------------------
Ran 48 tests in 1.545s

FAILED (failures=3, errors=23)